Calling thrower
Constructing
In catch
object(Exception) (7) {
  ["message":protected]=>
  string(7) "finally"
  ["string":"Exception":private]=>
  string(0) ""
  ["code":protected]=>
  int(0)
  ["file":protected]=>
  string(%d) "%s/test/slow/exceptions/chain-fault.php"
  ["line":protected]=>
  int(15)
  ["trace":"Exception":private]=>
  varray(2) {
    darray(4) {
      ["file"]=>
      string(%d) "%s/test/slow/exceptions/chain-fault.php"
      ["line"]=>
      int(22)
      ["function"]=>
      string(7) "thrower"
      ["args"]=>
      vec(0) {
      }
    }
    darray(2) {
      ["function"]=>
      string(4) "main"
      ["args"]=>
      vec(0) {
      }
    }
  }
  ["previous":"Exception":private]=>
  object(LogExn) (7) {
    ["message":protected]=>
    string(5) "inner"
    ["string":"Exception":private]=>
    string(0) ""
    ["code":protected]=>
    int(0)
    ["file":protected]=>
    string(%d) "%s/test/slow/exceptions/chain-fault.php"
    ["line":protected]=>
    int(13)
    ["trace":"Exception":private]=>
    varray(2) {
      darray(4) {
        ["file"]=>
        string(%d) "%s/test/slow/exceptions/chain-fault.php"
        ["line"]=>
        int(22)
        ["function"]=>
        string(7) "thrower"
        ["args"]=>
        vec(0) {
        }
      }
      darray(2) {
        ["function"]=>
        string(4) "main"
        ["args"]=>
        vec(0) {
        }
      }
    }
    ["previous":"Exception":private]=>
    NULL
  }
}
Leaving main
